<?xml version="1.0"?>
<<<<<<< HEAD
<robot name="kurt" xmlns:xacro="http://ros.org/wiki/xacro">

  <xacro:property name="PI" value="3.14159" />

  <xacro:property name="size" value="0.6 0.3 0.25" />
  <link name="kurt_body">
    <collision>
      <origin xyz="0.0 0.0 0.0"/>
      <geometry>
        <box size="${size}" />
      </geometry>
    </collision>
=======
<robot name="kurt">
  <link name="body">
>>>>>>> backup gazebo stuff
    <inertial>
      <origin xyz="0.0 0.0 0.0" /> 
      <mass value="1.0" />
      <inertia  ixx="1.0" ixy="0.0"  ixz="0.0"  iyy="1.0"  iyz="0.0"  izz="1.0" />
    </inertial>
    <visual>
      <origin xyz="0.0 0.0 0.0"/>
      <geometry>
<<<<<<< HEAD
        <box size="${size}" />
      </geometry>
      <material name="red"><color rgba="1 0 0 1"/></material>
    </visual>
  </link>


  <xacro:property name="kurt_wheel_length" value="0.03" />
  <xacro:property name="kurt_wheel_radius" value="0.07" />
  <xacro:macro name="kurt_wheel" params="xyz rpy">
    <collision>
      <origin xyz="${xyz}" rpy="${rpy}"/>
      <geometry>
        <cylinder length="${kurt_wheel_length}" radius="${kurt_wheel_radius}" />
      </geometry>
    </collision>
    <inertial>
      <origin xyz="${xyz}" rpy="${rpy}"/>
      <mass value="1.0" />
      <inertia  ixx="1.0" ixy="0.0"  ixz="0.0"  iyy="1.0"  iyz="0.0"  izz="1.0" />
    </inertial>
    <visual>
      <origin xyz="${xyz}" rpy="${rpy}"/>
      <geometry>
        <cylinder length="${kurt_wheel_length}" radius="${kurt_wheel_radius}" />
      </geometry>
      <material name="grey"><color rgba="0.5 0.5 0.5 1"/></material>
    </visual>
  </xacro:macro>
  <link name="kurt_wheel_left_front">
    <xacro:kurt_wheel xyz="0.2 0.17 -0.125" rpy="${PI/2} 0.0 0.0" />
  </link>
  <link name="kurt_wheel_left_back">
    <xacro:kurt_wheel xyz="-0.2 0.17 -0.125" rpy="${PI/2} 0.0 0.0" />
  </link>
  <link name="kurt_wheel_right_front">
    <xacro:kurt_wheel xyz="0.2 -0.17 -0.125" rpy="${PI/2} 0.0 0.0" />
  </link>
  <link name="kurt_wheel_right_back">
    <xacro:kurt_wheel xyz="-0.2 -0.17 -0.125" rpy="${PI/2} 0.0 0.0" />
  </link>

  <joint name="body_to_wheel_left_front" type="continuous">
    <parent link="kurt_body"/>
    <child link="kurt_wheel_left_front"/>
  </joint>

  <joint name="body_to_wheel_left_back" type="continuous">
    <parent link="kurt_body"/>
    <child link="kurt_wheel_left_back"/>
  </joint>

  <joint name="body_to_wheel_right_front" type="continuous">
    <parent link="kurt_body"/>
    <child link="kurt_wheel_right_front"/>
    <axis xyz="1 0 0"/>
    <origin xyz="0 0 0.3"/>
  </joint>

  <joint name="body_to_wheel_right_back" type="continuous">
    <parent link="kurt_body"/>
    <child link="kurt_wheel_right_back"/>
  </joint>


  <gazebo reference="kurt_body">
    <material>Gazebo/Red</material>
  </gazebo>
  <gazebo reference="kurt_wheel_left_front">
    <material>Gazebo/Grey</material>
  </gazebo>
  <gazebo reference="kurt_wheel_left_back">
    <material>Gazebo/Grey</material>
  </gazebo>
  <gazebo reference="kurt_wheel_right_front">
    <material>Gazebo/Grey</material>
  </gazebo>
  <gazebo reference="kurt_wheel_right_back">
    <material>Gazebo/Grey</material>
  </gazebo>
=======
        <box size="2.0 1.0 1.0" />
      </geometry>
    </visual>
    <collision>
      <origin xyz="0.0 0.0 0.0"/>
      <geometry>
        <box size="1.0 1.0 1.0" />
      </geometry>
    </collision>
  </link>
  <gazebo reference="body">
    <material>Gazebo/Red</material>
  </gazebo>
>>>>>>> backup gazebo stuff
</robot>


