<?xml version="1.0" ?>
<!-- =================================================================================== -->
<!-- |    This document was autogenerated by xacro from kurt.urdf.xacro                | -->
<!-- |    EDITING THIS FILE BY HAND IS NOT RECOMMENDED                                 | -->
<!-- =================================================================================== -->
<robot name="kurt" xmlns:xacro="http://ros.org/wiki/xacro">
  <link name="kurt_body">
    <collision>
      <origin xyz="0.0 0.0 0.0"/>
      <geometry>
        <box size="0.6 0.3 0.25"/>
      </geometry>
    </collision>
    <inertial>
      <origin xyz="0.0 0.0 0.0"/>
      <mass value="1.0"/>
      <inertia ixx="1.0" ixy="0.0" ixz="0.0" iyy="1.0" iyz="0.0" izz="1.0"/>
    </inertial>
    <visual>
      <origin xyz="0.0 0.0 0.0"/>
      <geometry>
        <box size="0.6 0.3 0.25"/>
      </geometry>
    </visual>
  </link>
  <link name="kurt_wheel_left_front">
    <collision>
      <origin rpy="1.570795 0.0 0.0" xyz="0.2 0.17 -0.125"/>
      <geometry>
        <cylinder length="0.03" radius="0.07"/>
      </geometry>
    </collision>
    <inertial>
      <origin rpy="1.570795 0.0 0.0" xyz="0.2 0.17 -0.125"/>
      <mass value="1.0"/>
      <inertia ixx="1.0" ixy="0.0" ixz="0.0" iyy="1.0" iyz="0.0" izz="1.0"/>
    </inertial>
    <visual>
      <origin rpy="1.570795 0.0 0.0" xyz="0.2 0.17 -0.125"/>
      <geometry>
        <cylinder length="0.03" radius="0.07"/>
      </geometry>
    </visual>
  </link>
  <link name="kurt_wheel_left_back">
    <collision>
      <origin rpy="1.570795 0.0 0.0" xyz="-0.2 0.17 -0.125"/>
      <geometry>
        <cylinder length="0.03" radius="0.07"/>
      </geometry>
    </collision>
    <inertial>
      <origin rpy="1.570795 0.0 0.0" xyz="-0.2 0.17 -0.125"/>
      <mass value="1.0"/>
      <inertia ixx="1.0" ixy="0.0" ixz="0.0" iyy="1.0" iyz="0.0" izz="1.0"/>
    </inertial>
    <visual>
      <origin rpy="1.570795 0.0 0.0" xyz="-0.2 0.17 -0.125"/>
      <geometry>
        <cylinder length="0.03" radius="0.07"/>
      </geometry>
    </visual>
  </link>
  <link name="kurt_wheel_right_front">
    <collision>
      <origin rpy="1.570795 0.0 0.0" xyz="0.2 -0.17 -0.125"/>
      <geometry>
        <cylinder length="0.03" radius="0.07"/>
      </geometry>
    </collision>
    <inertial>
      <origin rpy="1.570795 0.0 0.0" xyz="0.2 -0.17 -0.125"/>
      <mass value="1.0"/>
      <inertia ixx="1.0" ixy="0.0" ixz="0.0" iyy="1.0" iyz="0.0" izz="1.0"/>
    </inertial>
    <visual>
      <origin rpy="1.570795 0.0 0.0" xyz="0.2 -0.17 -0.125"/>
      <geometry>
        <cylinder length="0.03" radius="0.07"/>
      </geometry>
    </visual>
  </link>
  <link name="kurt_wheel_right_back">
    <collision>
      <origin rpy="1.570795 0.0 0.0" xyz="-0.2 -0.17 -0.125"/>
      <geometry>
        <cylinder length="0.03" radius="0.07"/>
      </geometry>
    </collision>
    <inertial>
      <origin rpy="1.570795 0.0 0.0" xyz="-0.2 -0.17 -0.125"/>
      <mass value="1.0"/>
      <inertia ixx="1.0" ixy="0.0" ixz="0.0" iyy="1.0" iyz="0.0" izz="1.0"/>
    </inertial>
    <visual>
      <origin rpy="1.570795 0.0 0.0" xyz="-0.2 -0.17 -0.125"/>
      <geometry>
        <cylinder length="0.03" radius="0.07"/>
      </geometry>
    </visual>
  </link>
  <joint name="body_to_wheel_left_front" type="continuous">
    <parent link="kurt_body"/>
    <child link="kurt_wheel_left_front"/>
  </joint>
  <joint name="body_to_wheel_left_back" type="continuous">
    <parent link="kurt_body"/>
    <child link="kurt_wheel_left_back"/>
  </joint>
  <joint name="body_to_wheel_right_front" type="continuous">
    <parent link="kurt_body"/>
    <child link="kurt_wheel_right_front"/>
    <axis xyz="0 1 0"/>
    <!--<origin xyz="0 0 0.3"/>-->
  </joint>
  <joint name="body_to_wheel_right_back" type="continuous">
    <parent link="kurt_body"/>
    <child link="kurt_wheel_right_back"/>
  </joint>
  <gazebo reference="kurt_body">
    <material>Gazebo/Red</material>
  </gazebo>
  <gazebo reference="kurt_wheel_left_front">
    <material>Gazebo/Grey</material>
  </gazebo>
  <gazebo reference="kurt_wheel_left_back">
    <material>Gazebo/Grey</material>
  </gazebo>
  <gazebo reference="kurt_wheel_right_front">
    <material>Gazebo/Grey</material>
  </gazebo>
  <gazebo reference="kurt_wheel_right_back">
    <material>Gazebo/Grey</material>
  </gazebo>
</robot>

